Workbook

Sheet 说明
A1: 人形机器人六维力传感器：需求测算与上市公司业务测算模型
A2: 版本 v0.3｜数据截止 2026-10-20｜配套：具身智能供应链简报.md
A4: 一、模型逻辑
A5: 客户 ROI（客户在什么条件下购买）→ 需求情景（整机出货 × 采用率 × 单机用量 × 单价）→ 收入桥（市场规模 × 公司份额 → 毛利、费用、净利润）→ 利润与估值（当前市值隐含的预期）→ 敏感性
A7: 二、工作表
A8: 假设：全模型唯一的参数来源；C4 为情景开关（1 悲观 / 2 基准 / 3 乐观）
A9: ROI：国内汽车工厂料箱搬运 / 上下料，三档同时展示
A10: 需求情景：2025A–2030E 中国人形六维力需求和市场规模；含 2025 校准与第三方预测对照
A11: 收入桥：柯力传感、安培龙、东华测试三家的相关业务收入和利润
A12: 利润与估值：市值 − 原有业务价值 − 投资资产 → 隐含新业务价值 → 折算到 2029 年末 → 所需 2030E 利润和份额
A13: 敏感性：市场规模（有效颗/台 × 单价）；柯力净利润（份额 × 毛利率）
A14: 数据底稿：256 条证据（C 公司 / D 需求与价格 / R ROI / F 统一口径行情与财务复核 / B 整机 BOM 参照），含原文要点、来源、日期、性质、局限；“本文采用值”列标明被哪个假设引用
... A29: 5. 本模型为个人研究作品，不构成投资建议。

Sheet 假设
A1: 假设：全模型唯一的参数来源
A2: 修改蓝色数字即可；黄色底色 = 作者假设或关键杠杆，需重点复核。G 列按情景开关自动取值，其他页面只引用本页。
B4: 情景开关（1=悲观，2=基准，3=乐观） | C4: 2 | D4: =CHOOSE($C$4,"悲观","基准","乐观")
A6: 编号 | B6: 参数 | C6: 单位 | D6: 悲观 | E6: 基准 | F6: 乐观 | G6: 选用值 | H6: 底稿 ID | I6: 依据 / 说明
A7: A. 客户 ROI：国内汽车工厂线边料箱搬运 / 上下料（单台）
A8: roi_inv | B8: 初始投入（整机 + 部署集成） | C8: 万元 | D8: 70 | E8: 50 | F8: 22 | G8: =CHOOSE($C$4,D8,E8,F8) | H8: R-01,R-03,R-05,R-07,R-10 | I8: 悲观：东风柳汽入厂成本六七十万（R-05）；基准：优必选含软件交付方案≤50 万、钛媒体进厂 TCO 50–60 万（R-03、R-07）；乐观：宇树 H2 19.9 万 + 约 2 万部署（部署额为作者假设，该机型的工业能力未经验证）
A9: roi_hrs | B9: 计划工时 | C9: 小时/年 | D9: 2000 | E9: 4000 | F9: 5600 | G9: =CHOOSE($C$4,D9,E9,F9) | H9: R-33,R-59,R-63,R-64 | I9: 单班 8h×250 天 / 两班 16h×250 天 / 三班 22.5h×250 天（三班依赖换电，R-41）
A10: roi_av | B10: 可用率（充换电、故障、调校停机） | C10: 比例 | D10: 0.75 | E10: 0.85 | F10: 0.95 | G10: =CHOOSE($C$4,D10,E10,F10) | H10: R-41,R-42 | I10: 悲观：Walker S1 工作 3 小时多、充电 1 小时（R-42）；基准：作者假设；乐观：Walker S2 3 分钟换电（R-41），余量 5% 为作者假设
A11: roi_sp | B11: 相对人工作业速度 | C11: 比例 | D11: 0.3 | E11: 0.45 | F11: 0.7 | G11: =CHOOSE($C$4,D11,E11,F11) | H11: R-19,R-21,R-25,R-26,R-39,R-66 | I11: 悲观：优必选 30%、小米长任务 30%；基准：优必选 45%、东风柳汽“顶半个工人”；乐观：小米短任务 70%–80%、智元 70% 以上。均为公司自报，无第三方测量
A12: roi_sr | B12: 任务成功率 | C12: 比例 | D12: 0.9 | E12: 0.98 | F12: 0.995 | G12: =CHOOSE($C$4,D12,E12,F12) | H12: R-19,R-27,R-29,R-31,R-37 | I12: 悲观：小米初期 90.2%；基准：乐聚在兆丰 98%、小米 98%；乐观：智元 99.5%。失败件按比例扣减产出（作者处理方式）
A13: roi_ph | B13: 单人年工时 | C13: 小时/年 | D13: 2000 | E13: 2000 | F13: 2000 | G13: =CHOOSE($C$4,D13,E13,F13) | H13: R-64 | I13: 作者假设：250 天×8 小时。人均实际工时更高则节省额被高估
A14: roi_lc | B14: 单人年综合用工成本 | C14: 万元/人·年 | D14: 9.5 | E14: 10.5 | F14: 14 | G14: =CHOOSE($C$4,D14,E14,F14) | H14: R-55,R-57,R-58,R-59,R-61 | I14: 悲观：汽车行业薪酬中位数 7.31 万×1.3；基准：规上生产制造人员 8.07 万×1.3；乐观：亨通工厂普工综合成本 14 万。社保倍数 1.3 为作者假设
A15: roi_mt | B15: 软件与维保年费（占初始投入） | C15: 比例/年 | D15: 0.15 | E15: 0.1 | F15: 0.05 | G15: =CHOOSE($C$4,D15,E15,F15) | H15: R-47,R-50,R-52 | I15: 全部为作者假设：国内费率未找到（R-52）。唯一外部锚点 Agility 厂商成本约 7.5%、客户收费约 18%（R-50）
A16: roi_sup | B16: 监管工程师配比 | C16: 人/台 | D16: 0.5 | E16: 0.25 | F16: 0.1 | G16: =CHOOSE($C$4,D16,E16,F16) | H16: R-34,R-45 | I16: 基准：乐聚在兆丰 1 名工程师照看 4 台；悲观：两班各 1:4（作者推断）；乐观：成熟期 1:10（作者假设）
A17: roi_ec | B17: 工程师年综合成本 | C17: 万元/人·年 | D17: 14.8 | E17: 14.8 | F17: 14.8 | G17: =CHOOSE($C$4,D17,E17,F17) | H17: R-55 | I17: 制造业非私营 11.36 万×1.3（倍数为作者假设）
A18: roi_en | B18: 能耗 | C18: 元/小时 | D18: 1 | E18: 0.8 | F18: 0.6 | G18: =CHOOSE($C$4,D18,E18,F18) | H18: R-51 | I18: 约 1kWh/小时 × 工业电价 0.6–1 元/kWh（作者推算），影响很小
A19: roi_tgt | B19: 目标回本期（用于反推所需速度） | C19: 年 | D19: 5 | E19: 5 | F19: 5 | G19: =CHOOSE($C$4,D19,E19,F19) | H19: — | I19: 作者设定的参照值，可修改
A20: B. 需求：中国人形机器人六维力传感器
A21: sh25 | B21: 2025 中国人形整机出货（实际） | C21: 万台 | D21: 1.8 | E21: 1.8 | F21: 1.8 | G21: =CHOOSE($C$4,D21,E21,F21) | H21: D-74 | I21: GGII：只计已交付、已验收。赛迪 1.44 万台、摩根士丹利对外销售 1.2 万台作对照（D-75、D-76）
A22: sh26 | B22: 2026E 中国人形整机出货 | C22: 万台 | D22: 4.8 | E22: 6.25 | F22: 8 | G22: =CHOOSE($C$4,D22,E22,F22) | H22: D-78,D-80 | I22: 悲观：MIR 出货 4.8 万；基准：GGII 6.25 万；乐观：作者假设 8 万（2026H1 已达 1.9 万台，IDC；工信部等 10 万+ 为产量口径，不作出货）
A23: sh30 | B23: 2030E 中国人形整机出货 | C23: 万台 | D23: 25 | E23: 44.6 | F23: 58.4 | G23: =CHOOSE($C$4,D23,E23,F23) | H23: D-81,D-83,D-78 | I23: 基准：摩根士丹利 44.6 万（二手）；乐观：IDC 全球 75 万+ × 2026H1 中国占比 77.9% ≈ 58.4 万（推算）；悲观：作者假设 25 万（约为基准的 56%）
A24: ad25 | B24: 2025 六维力搭载率（搭载台数 ÷ 总出货台数） | C24: 比例 | D24: 0.2 | E24: 0.28 | F24: 0.35 | G24: =CHOOSE($C$4,D24,E24,F24) | H24: D-23,D-25,D-26,D-27 | I24: 按出货台数口径：GGII / 赛迪 2025 年传感器用量 ÷ 整机出货，得每台平均 0.68–0.92 颗，再按搭载机型每台 2.7–3 颗折算约 23%–34%；中金 2024 年 20%
A25: ad26 | B25: 2026E 搭载率 | C25: 比例 | D25: 0.25 | E25: 0.33 | F25: 0.4 | G25: =CHOOSE($C$4,D25,E25,F25) | H25: D-29,D-30 | I25: 工业场景占比上升，六维力“可选变必须”
A26: ad30 | B26: 2030E 搭载率 | C26: 比例 | D26: 0.35 | E26: 0.55 | F26: 0.7 | G26: =CHOOSE($C$4,D26,E26,F26) | H26: D-23,D-24,D-28 | I26: 基准：中金 55%；悲观：协作机器人约 25% + 工业增量；乐观：接近赛迪隐含 3 颗/台。中金原文为“渗透率”，未说明按型号还是按出货台数，本文按出货台数口径使用，待核原文
A27: units | B27: 单机用量（每台配置机型） | C27: 颗/台 | D27: 2 | E27: 3 | F27: 4 | G27: =CHOOSE($C$4,D27,E27,F27) | H27: D-01,D-02,D-03,D-06,D-10,D-18,D-19 | I27: 2 颗：只配腕部（Walker S2、智元 A2-W、银河通用 Galbot G1）；4 颗：腕 + 踝（Walker X/S1）；宇树、智元 A2 双足版官方未列六维力（D-31）
A28: p25 | B28: 2025 国产人形专用单价 | C28: 元/颗 | D28: 12000 | E28: 20000 | F28: 25000 | G28: =CHOOSE($C$4,D28,E28,F28) | H28: D-48,D-49,D-52 | I28: 悲观列：国信 1–2 万、中金 1 万；基准：GGII 隐含 2.0 万；乐观列：赛迪隐含 2.5 万。进口 7–8 万只作对照（D-50、C-71）
A29: d1 | B29: 年降价幅度 2026–2027 | C29: 比例/年 | D29: 0.15 | E29: 0.25 | F29: 0.35 | G29: =CHOOSE($C$4,D29,E29,F29) | H29: D-52,D-53,D-54 | I29: 量价反向搭配：采用率越高，规模效应带来的降价越快。赛迪“1–2 年再降 30%”、华宝每年 -15%、中金年均约 -29%
A30: d2 | B30: 年降价幅度 2028–2030 | C30: 比例/年 | D30: 0.1 | E30: 0.2 | F30: 0.25 | G30: =CHOOSE($C$4,D30,E30,F30) | H30: D-52,D-53 | I30: 中金 2027 年后每年 -10%；华宝 -15% 至 -21%
A31: C. 公司：份额与利润率（六维力 / 机器人力传感器相关业务）
A32: gm | B32: 相关业务毛利率 | C32: 比例 | D32: 0.3 | E32: 0.4 | F32: 0.5 | G32: =CHOOSE($C$4,D32,E32,F32) | H32: C-25,C-35,D-44,D-57 | I32: 柯力 2025 综合毛利率 44.83%（C-25）；安培龙力传感器募投项目达产毛利率 37.77%（C-35）；人形专用型号毛利率未找到，降价期取区间
A33: opex | B33: 增量期间费用率（销售 + 管理 + 研发） | C33: 比例 | D33: 0.15 | E33: 0.12 | F33: 0.1 | G33: =CHOOSE($C$4,D33,E33,F33) | H33: — | I33: 作者假设：新业务需持续研发和送样投入；规模越大费用率越低
A34: tax | B34: 所得税率 | C34: 比例 | D34: 0.15 | E34: 0.15 | F34: 0.15 | G34: =CHOOSE($C$4,D34,E34,F34) | H34: — | I34: 高新技术企业 15%（作者假设三家均适用）
A35: ky_s26 | B35: 柯力传感 2026E 份额 | C35: 比例 | D35: 0.05 | E35: 0.05 | F35: 0.05 | G35: =CHOOSE($C$4,D35,E35,F35) | H35: C-12,C-21,D-65 | I35: 柯力 2026H1 机器人力学传感器 2,000+ 只（含关节力矩、协作机器人，C-12），国金预计全年约 1.2 万只（C-21）；基准 2026E 中国人形六维力需求约 6.19 万颗，5% 约 3,100 颗；赛迪 2025 年前三家合计 92.8%，其余厂商合计 ≤7.2%（D-65）
A36: ky_s30 | B36: 柯力传感 2030E 份额 | C36: 比例 | D36: 0.03 | E36: 0.08 | F36: 0.15 | G36: =CHOOSE($C$4,D36,E36,F36) | H36: C-08,C-14,C-15,C-16 | I36: 已进入批量过渡、送样 90+ 家，但头部客户仍在验证、批量客户开普勒为关联方；份额为作者假设区间
A37: ap_s26 | B37: 安培龙 2026E 份额 | C37: 比例 | D37: 0.02 | E37: 0.02 | F37: 0.02 | G37: =CHOOSE($C$4,D37,E37,F37) | H37: C-38,C-39 | I37: 2026-09 部分客户批量交付，收入占比低（作者假设）
A38: ap_s30 | B38: 安培龙 2030E 份额 | C38: 比例 | D38: 0.01 | E38: 0.05 | F38: 0.1 | G38: =CHOOSE($C$4,D38,E38,F38) | H38: C-35,C-39 | I38: 定增新增年产约 50 万只力传感器（含六维力，计划）；份额为作者假设区间
A39: dh_s26 | B39: 东华测试 2026E 份额 | C39: 比例 | D39: 0 | E39: 0 | F39: 0 | G39: =CHOOSE($C$4,D39,E39,F39) | H39: C-46,C-47,C-50 | I39: 无人形六维力订单，仍为小批量试制 / 关节模组发布
A40: dh_s30 | B40: 东华测试 2030E 份额 | C40: 比例 | D40: 0 | E40: 0.01 | F40: 0.03 | G40: =CHOOSE($C$4,D40,E40,F40) | H40: C-50,C-51 | I40: 技术储备与检测能力存在，但无兑现证据（作者假设）
A41: D. 估值：当前市值隐含什么预期
A42: ky_mc | B42: 柯力传感 总市值 | C42: 亿元 | D42: 122.25 | E42: 122.25 | F42: 122.25 | G42: =CHOOSE($C$4,D42,E42,F42) | H42: F-01 | I42: Findesk（iFinD 数据）2026-10-19 收盘：不复权收盘价 × 总股本 = 122.25 亿元
...

Sheet ROI
A1: 客户 ROI：国内汽车工厂线边料箱搬运 / 上下料（单台人形机器人）
A2: 回本期 = 初始投入 ÷（年节省人工 − 年新增运维）；年净节省 ≤ 0 时显示“无法回本”。三列同时展示，不受情景开关影响。
A4: 项目 | B4: 单位 | C4: 悲观 | D4: 中性 | E4: 乐观 | F4: 公式 / 说明
A5: 输入（引自「假设」页）
A6: 初始投入 | B6: 万元 | C6: =假设!D8 | D6: =假设!E8 | E6: =假设!F8
A7: 计划工时 | B7: 小时/年 | C7: =假设!D9 | D7: =假设!E9 | E7: =假设!F9
A8: 可用率 | B8: 比例 | C8: =假设!D10 | D8: =假设!E10 | E8: =假设!F10
A9: 相对人工速度 | B9: 比例 | C9: =假设!D11 | D9: =假设!E11 | E9: =假设!F11
A10: 成功率 | B10: 比例 | C10: =假设!D12 | D10: =假设!E12 | E10: =假设!F12
A11: 单人年工时 | B11: 小时/年 | C11: =假设!D13 | D11: =假设!E13 | E11: =假设!F13
A12: 单人年综合用工成本 | B12: 万元 | C12: =假设!D14 | D12: =假设!E14 | E12: =假设!F14
A13: 软件与维保年费率 | B13: 比例 | C13: =假设!D15 | D13: =假设!E15 | E13: =假设!F15
A14: 监管工程师配比 | B14: 人/台 | C14: =假设!D16 | D14: =假设!E16 | E14: =假设!F16
A15: 工程师年综合成本 | B15: 万元 | C15: =假设!D17 | D15: =假设!E17 | E15: =假设!F17
A16: 能耗 | B16: 元/小时 | C16: =假设!D18 | D16: =假设!E18 | E16: =假设!F18
A17: 目标回本期 | B17: 年 | C17: =假设!D19 | D17: =假设!E19 | E17: =假设!F19
A18: 计算
A19: 有效替代工时 | B19: 小时/年 | C19: =C7*C8*C9*C10 | D19: =D7*D8*D9*D10 | E19: =E7*E8*E9*E10 | F19: 计划工时 × 可用率 × 速度 × 成功率
A20: 等效替代人力 | B20: 人·年 | C20: =C19/C11 | D20: =D19/D11 | E20: =E19/E11 | F20: 有效替代工时 ÷ 单人年工时
A21: 年节省人工成本 | B21: 万元 | C21: =C20*C12 | D21: =D20*D12 | E21: =E20*E12
A22: 软件与维保费 | B22: 万元 | C22: =C6*C13 | D22: =D6*D13 | E22: =E6*E13
A23: 监管工程师分摊 | B23: 万元 | C23: =C14*C15 | D23: =D14*D15 | E23: =E14*E15
A24: 能耗 | B24: 万元 | C24: =C7*C8*C16/10000 | D24: =D7*D8*D16/10000 | E24: =E7*E8*E16/10000
A25: 年新增运维合计 | B25: 万元 | C25: =C22+C23+C24 | D25: =D22+D23+D24 | E25: =E22+E23+E24
A26: 年净节省 | B26: 万元 | C26: =C21-C25 | D26: =D21-D25 | E26: =E21-E25
A27: 回本期 | B27: 年 | C27: =IF(C26<=0,"无法回本",C6/C26) | D27: =IF(D26<=0,"无法回本",D6/D26) | E27: =IF(E26<=0,"无法回本",E6/E26) | F27: 净节省 ≤ 0 时无法回本
A28: 达到目标回本期所需的相对速度 | B28: 比例 | C28: =(C6/C17+C25)/C12*C11/(C7*C8*C10) | D28: =(D6/D17+D25)/D12*D11/(D7*D8*D10) | E28: =(E6/E17+E25)/E12*E11/(E7*E8*E10) | F28: 其余参数不变时；>100% 表示需要超过人工速度
A30: 外部测算对照（口径不同，只作参照）
A31: 伯恩斯坦：中国工厂搬运约 6.7 年（R-70）
A32: 乐聚兆丰自测 2–4 年，但董事长称最初未算采购成本（R-31、R-34）
A33: 常琳：约 2 年“拉平”，未含维保费（R-66）
A34: GGII：汽车行业“年 ROI”0.8（口径不明）

Sheet 需求情景
A1: 需求情景：中国人形机器人六维力传感器（按情景开关）
A2: ="当前情景："&假设!$D$4
A4: 项目 | B4: 单位 | C4: 2025A | D4: 2026E | E4: 2027E | F4: 2028E | G4: 2029E | H4: 2030E | I4: 说明
A5: 中国人形整机出货 | B5: 万台 | C5: =假设!$G$21 | D5: =假设!$G$22 | E5: =$D5*($H5/$D5)^((2-1)/4) | F5: =$D5*($H5/$D5)^((3-1)/4) | G5: =$D5*($H5/$D5)^((4-1)/4) | H5: =假设!$G$23 | I5: 2027–2029 按 2026→2030 年复合增速插值
A6: 六维力搭载率（按出货台数） | B6: 比例 | C6: =假设!$G$24 | D6: =假设!$G$25 | E6: =$D6+($H6-$D6)*1/4 | F6: =$D6+($H6-$D6)*2/4 | G6: =$D6+($H6-$D6)*3/4 | H6: =假设!$G$26 | I6: 2027–2029 线性插值
A7: 单机用量（配置机型） | B7: 颗/台 | C7: =假设!$G$27 | D7: =假设!$G$27 | E7: =假设!$G$27 | F7: =假设!$G$27 | G7: =假设!$G$27 | H7: =假设!$G$27
A8: 有效颗/台 | B8: 颗/台 | C8: =C6*C7 | D8: =D6*D7 | E8: =E6*E7 | F8: =F6*F7 | G8: =G6*G7 | H8: =H6*H7 | I8: 搭载率 × 单机用量
A9: 六维力需求 | B9: 万颗 | C9: =C5*C8 | D9: =D5*D8 | E9: =E5*E8 | F9: =F5*F8 | G9: =G5*G8 | H9: =H5*H8 | I9: 整机出货 × 有效颗/台
A10: 单价 | B10: 元/颗 | C10: =假设!$G$28 | D10: =C10*(1-假设!$G$29) | E10: =D10*(1-假设!$G$29) | F10: =E10*(1-假设!$G$30) | G10: =F10*(1-假设!$G$30) | H10: =G10*(1-假设!$G$30) | I10: 2026–2027 用降幅 1，2028–2030 用降幅 2
A11: 市场规模 | B11: 亿元 | C11: =C9*C10/10000 | D11: =D9*D10/10000 | E11: =E9*E10/10000 | F11: =F9*F10/10000 | G11: =G9*G10/10000 | H11: =H9*H10/10000 | I11: 需求（万颗）× 单价 ÷ 10,000
A12: 市场规模同比 | B12: 比例 | D12: =IF(C11=0,0,D11/C11-1) | E12: =IF(D11=0,0,E11/D11-1) | F12: =IF(E11=0,0,F11/E11-1) | G12: =IF(F11=0,0,G11/F11-1) | H12: =IF(G11=0,0,H11/G11-1)
A14: 2025 年校准：模型 vs 第三方实际
A15: 来源 | B15: 单位 | C15: 需求 | D15: 市场规模（亿元） | E15: 隐含均价（元） | I15: 说明
A16: 本模型（当前情景） | B16: 万颗 | C16: =C9 | D16: =C11 | E16: =C10 | I16: —
A17: GGII（2025-11，年内预估） | B17: 万颗 | C17: 1.23 | D17: 2.46 | E17: =D17/C17*10000 | I17: D-25 / research：1.23 万台、2.46 亿元
A18: 赛迪 × 中国电子报（2026-08，年度回顾） | B18: 万颗 | C18: 1.32 | D18: 3.3 | E18: =D18/C18*10000 | I18: D-26 / D-64：1.32 万颗、3.3 亿元
A20: 2030E 三情景对比（不受开关影响）与第三方预测
A21: 项目 | B21: 单位 | C21: 悲观 | D21: 基准 | E21: 乐观 | F21: GGII | G21: 赛迪 | I21: 说明
A22: 整机出货 | B22: 万台 | C22: =假设!D23 | D22: =假设!E23 | E22: =假设!F23 | G22: 40 | I22: 赛迪 40 万台只见于解读稿
A23: 有效颗/台 | B23: 颗/台 | C23: =假设!D26*假设!D27 | D23: =假设!E26*假设!E27 | E23: =假设!F26*假设!F27
A24: 需求 | B24: 万颗 | C24: =C22*C23 | D24: =D22*D23 | E24: =E22*E23 | F24: 46 | G24: 120 | I24: GGII 46 万台（颗）、赛迪 120 万颗
A25: 单价 | B25: 元/颗 | C25: =假设!D28*(1-假设!D29)^2*(1-假设!D30)^3 | D25: =假设!E28*(1-假设!E29)^2*(1-假设!E30)^3 | E25: =假设!F28*(1-假设!F29)^2*(1-假设!F30)^3 | F25: 3900 | G25: 5000 | I25: 第三方为隐含均价
A26: 市场规模 | B26: 亿元 | C26: =C24*C25/10000 | D26: =D24*D25/10000 | E26: =E24*E25/10000 | F26: 18 | G26: 60 | I26: D-61、D-64

Sheet 收入桥
A1: 收入桥：行业需求 → 公司相关业务收入与利润（按情景开关）
A2: 相关业务收入 = 中国人形出货 × 采用率 × 单机用量 × 单价 × 公司份额 = 市场规模 × 公司份额
A4: 项目 | B4: 单位 | C4: 2026E | D4: 2027E | E4: 2028E | F4: 2029E | G4: 2030E | H4: 说明
A5: 行业
A6: 中国人形六维力市场规模 | B6: 亿元 | C6: =需求情景!D11 | D6: =需求情景!E11 | E6: =需求情景!F11 | F6: =需求情景!G11 | G6: =需求情景!H11
A8: 柯力传感（603662）
A9: 份额 | B9: 比例 | C9: =假设!$G$35+(假设!$G$36-假设!$G$35)*0/4 | D9: =假设!$G$35+(假设!$G$36-假设!$G$35)*1/4 | E9: =假设!$G$35+(假设!$G$36-假设!$G$35)*2/4 | F9: =假设!$G$35+(假设!$G$36-假设!$G$35)*3/4 | G9: =假设!$G$35+(假设!$G$36-假设!$G$35)*4/4 | H9: 2026→2030 线性
A10: 相关业务收入 | B10: 亿元 | C10: =C$6*C9 | D10: =D$6*D9 | E10: =E$6*E9 | F10: =F$6*F9 | G10: =G$6*G9
A11: 毛利 | B11: 亿元 | C11: =C10*假设!$G$32 | D11: =D10*假设!$G$32 | E11: =E10*假设!$G$32 | F11: =F10*假设!$G$32 | G11: =G10*假设!$G$32
A12: 增量期间费用 | B12: 亿元 | C12: =C10*假设!$G$33 | D12: =D10*假设!$G$33 | E12: =E10*假设!$G$33 | F12: =F10*假设!$G$33 | G12: =G10*假设!$G$33
A13: 相关业务净利润 | B13: 亿元 | C13: =(C11-C12)*(1-假设!$G$34) | D13: =(D11-D12)*(1-假设!$G$34) | E13: =(E11-E12)*(1-假设!$G$34) | F13: =(F11-F12)*(1-假设!$G$34) | G13: =(G11-G12)*(1-假设!$G$34)
A14: 相关业务净利润 ÷ 2025A 扣非净利润 | B14: 比例 | C14: =IF(假设!$G$43=0,0,C13/假设!$G$43) | D14: =IF(假设!$G$43=0,0,D13/假设!$G$43) | E14: =IF(假设!$G$43=0,0,E13/假设!$G$43) | F14: =IF(假设!$G$43=0,0,F13/假设!$G$43) | G14: =IF(假设!$G$43=0,0,G13/假设!$G$43) | H14: 增量利润相当于历史利润的多少，不是占未来总利润的比例
A15: 新业务占 2030E 总利润 | B15: 比例 | C15: =IF((C13+假设!$G$43)=0,0,C13/(C13+假设!$G$43)) | D15: =IF((D13+假设!$G$43)=0,0,D13/(D13+假设!$G$43)) | E15: =IF((E13+假设!$G$43)=0,0,E13/(E13+假设!$G$43)) | F15: =IF((F13+假设!$G$43)=0,0,F13/(F13+假设!$G$43)) | G15: =IF((G13+假设!$G$43)=0,0,G13/(G13+假设!$G$43)) | H15: 假设原有业务利润保持 2025A 扣非水平
A16: 安培龙（301413）
A17: 份额 | B17: 比例 | C17: =假设!$G$37+(假设!$G$38-假设!$G$37)*0/4 | D17: =假设!$G$37+(假设!$G$38-假设!$G$37)*1/4 | E17: =假设!$G$37+(假设!$G$38-假设!$G$37)*2/4 | F17: =假设!$G$37+(假设!$G$38-假设!$G$37)*3/4 | G17: =假设!$G$37+(假设!$G$38-假设!$G$37)*4/4 | H17: 2026→2030 线性
A18: 相关业务收入 | B18: 亿元 | C18: =C$6*C17 | D18: =D$6*D17 | E18: =E$6*E17 | F18: =F$6*F17 | G18: =G$6*G17
A19: 毛利 | B19: 亿元 | C19: =C18*假设!$G$32 | D19: =D18*假设!$G$32 | E19: =E18*假设!$G$32 | F19: =F18*假设!$G$32 | G19: =G18*假设!$G$32
A20: 增量期间费用 | B20: 亿元 | C20: =C18*假设!$G$33 | D20: =D18*假设!$G$33 | E20: =E18*假设!$G$33 | F20: =F18*假设!$G$33 | G20: =G18*假设!$G$33
A21: 相关业务净利润 | B21: 亿元 | C21: =(C19-C20)*(1-假设!$G$34) | D21: =(D19-D20)*(1-假设!$G$34) | E21: =(E19-E20)*(1-假设!$G$34) | F21: =(F19-F20)*(1-假设!$G$34) | G21: =(G19-G20)*(1-假设!$G$34)
A22: 相关业务净利润 ÷ 2025A 扣非净利润 | B22: 比例 | C22: =IF(假设!$G$45=0,0,C21/假设!$G$45) | D22: =IF(假设!$G$45=0,0,D21/假设!$G$45) | E22: =IF(假设!$G$45=0,0,E21/假设!$G$45) | F22: =IF(假设!$G$45=0,0,F21/假设!$G$45) | G22: =IF(假设!$G$45=0,0,G21/假设!$G$45) | H22: 增量利润相当于历史利润的多少，不是占未来总利润的比例
A23: 新业务占 2030E 总利润 | B23: 比例 | C23: =IF((C21+假设!$G$45)=0,0,C21/(C21+假设!$G$45)) | D23: =IF((D21+假设!$G$45)=0,0,D21/(D21+假设!$G$45)) | E23: =IF((E21+假设!$G$45)=0,0,E21/(E21+假设!$G$45)) | F23: =IF((F21+假设!$G$45)=0,0,F21/(F21+假设!$G$45)) | G23: =IF((G21+假设!$G$45)=0,0,G21/(G21+假设!$G$45)) | H23: 假设原有业务利润保持 2025A 扣非水平
A24: 东华测试（300354）
A25: 份额 | B25: 比例 | C25: =假设!$G$39+(假设!$G$40-假设!$G$39)*0/4 | D25: =假设!$G$39+(假设!$G$40-假设!$G$39)*1/4 | E25: =假设!$G$39+(假设!$G$40-假设!$G$39)*2/4 | F25: =假设!$G$39+(假设!$G$40-假设!$G$39)*3/4 | G25: =假设!$G$39+(假设!$G$40-假设!$G$39)*4/4 | H25: 2026→2030 线性
A26: 相关业务收入 | B26: 亿元 | C26: =C$6*C25 | D26: =D$6*D25 | E26: =E$6*E25 | F26: =F$6*F25 | G26: =G$6*G25
A27: 毛利 | B27: 亿元 | C27: =C26*假设!$G$32 | D27: =D26*假设!$G$32 | E27: =E26*假设!$G$32 | F27: =F26*假设!$G$32 | G27: =G26*假设!$G$32
A28: 增量期间费用 | B28: 亿元 | C28: =C26*假设!$G$33 | D28: =D26*假设!$G$33 | E28: =E26*假设!$G$33 | F28: =F26*假设!$G$33 | G28: =G26*假设!$G$33
A29: 相关业务净利润 | B29: 亿元 | C29: =(C27-C28)*(1-假设!$G$34) | D29: =(D27-D28)*(1-假设!$G$34) | E29: =(E27-E28)*(1-假设!$G$34) | F29: =(F27-F28)*(1-假设!$G$34) | G29: =(G27-G28)*(1-假设!$G$34)
A30: 相关业务净利润 ÷ 2025A 扣非净利润 | B30: 比例 | C30: =IF(假设!$G$47=0,0,C29/假设!$G$47) | D30: =IF(假设!$G$47=0,0,D29/假设!$G$47) | E30: =IF(假设!$G$47=0,0,E29/假设!$G$47) | F30: =IF(假设!$G$47=0,0,F29/假设!$G$47) | G30: =IF(假设!$G$47=0,0,G29/假设!$G$47) | H30: 增量利润相当于历史利润的多少，不是占未来总利润的比例
A31: 新业务占 2030E 总利润 | B31: 比例 | C31: =IF((C29+假设!$G$47)=0,0,C29/(C29+假设!$G$47)) | D31: =IF((D29+假设!$G$47)=0,0,D29/(D29+假设!$G$47)) | E31: =IF((E29+假设!$G$47)=0,0,E29/(E29+假设!$G$47)) | F31: =IF((F29+假设!$G$47)=0,0,F29/(F29+假设!$G$47)) | G31: =IF((G29+假设!$G$47)=0,0,G29/(G29+假设!$G$47)) | H31: 假设原有业务利润保持 2025A 扣非水平

Sheet 利润与估值
A1: 利润与估值：当前市值隐含了多少新业务预期（按情景开关）
A2: 思路：当前市值 − 原有业务价值 − 非经营性投资资产 = 隐含新业务价值 → 折算到 2029 年末 → ÷ 前瞻 PE = 所需 2030E 净利润 → ÷（市场规模 × 净利率）= 所需份额。
A4: 项目 | B4: 单位 | C4: 柯力传感 | D4: 安培龙 | E4: 东华测试 | F4: 说明
A5: 总市值 | B5: 亿元 | C5: =假设!$G$42 | D5: =假设!$G$44 | E5: =假设!$G$46 | F5: 2026-10-19 收盘价 × 总股本（F-01、F-03、F-05）
A6: 原有业务净利润（2025A 扣非） | B6: 亿元 | C6: =假设!$G$43 | D6: =假设!$G$45 | E6: =假设!$G$47 | F6: 扣非利润已含利息收支
A7: 原有业务 PE | B7: x | C7: =假设!$G$48 | D7: =假设!$G$48 | E7: =假设!$G$48
A8: ① 原有业务价值 | B8: 亿元 | C8: =C6*C7 | D8: =D6*D7 | E8: =E6*E7 | F8: 扣非净利润 × PE
A9: ② 非经营性投资资产（2026-06-30 账面） | B9: 亿元 | C9: =假设!$G$50 | D9: =假设!$G$51 | E9: =假设!$G$52 | F9: 理财、金融资产、长期股权投资，收益多不在扣非利润中
A10: ③ 隐含新业务价值（报告日） | B10: 亿元 | C10: =C5-C8-C9 | D10: =D5-D8-D9 | E10: =E5-E8-E9 | F10: ≤ 0 表示市值未给新业务溢价
A11: 新业务价值占总市值 | B11: 比例 | C11: =IF(C5=0,0,C10/C5) | D11: =IF(D5=0,0,D10/D5) | E11: =IF(E5=0,0,E10/E5)
A12: 股权折现率 | B12: 比例 | C12: =假设!$G$56 | D12: =假设!$G$56 | E12: =假设!$G$56 | F12: 作者假设
A13: 折现年数 | B13: 年 | C13: =假设!$G$57 | D13: =假设!$G$57 | E13: =假设!$G$57 | F13: 报告日至 2029 年末
A14: ④ 新业务价值（折算到 2029 年末） | B14: 亿元 | C14: =MAX(0,C10)*(1+C12)^C13 | D14: =MAX(0,D10)*(1+D12)^D13 | E14: =MAX(0,E10)*(1+E12)^E13 | F14: 2029 年末按 2030E 利润 × 前瞻 PE 定价
A15: 新业务稳态 PE（2030E） | B15: x | C15: =假设!$G$49 | D15: =假设!$G$49 | E15: =假设!$G$49
A16: ⑤ 所需 2030E 新业务净利润 | B16: 亿元 | C16: =C14/C15 | D16: =D14/D15 | E16: =E14/E15
A17: 相关业务净利率 | B17: 比例 | C17: =(假设!$G$32-假设!$G$33)*(1-假设!$G$34) | D17: =(假设!$G$32-假设!$G$33)*(1-假设!$G$34) | E17: =(假设!$G$32-假设!$G$33)*(1-假设!$G$34) | F17: （毛利率 − 费用率）×（1 − 所得税率）
A18: 2030E 中国人形六维力市场规模 | B18: 亿元 | C18: =需求情景!H11 | D18: =需求情景!H11 | E18: =需求情景!H11
A19: ⑥ 支撑当前市值所需的 2030E 份额 | B19: 比例 | C19: =IF(C18*C17=0,0,C16/(C18*C17)) | D19: =IF(D18*D17=0,0,D16/(D18*D17)) | E19: =IF(E18*E17=0,0,E16/(E18*E17)) | F19: 对照：2025 年前三名合计 92.8%（赛迪）
A20: 模型假设的 2030E 份额 | B20: 比例 | C20: =收入桥!G9 | D20: =收入桥!G17 | E20: =收入桥!G25
A21: 模型 2030E 相关业务净利润 | B21: 亿元 | C21: =收入桥!G13 | D21: =收入桥!G21 | E21: =收入桥!G29 | F21: 引自「收入桥」
A22: 模型利润 ÷ 所需利润 | B22: 比例 | C22: =IF(C16=0,"无需兑现",C21/C16) | D22: =IF(D16=0,"无需兑现",D21/D16) | E22: =IF(E16=0,"无需兑现",E21/E16) | F22: <100% 表示按本模型仍不足以支撑当前市值
A24: 参考：净现金（负数为净负债） | B24: 亿元 | C24: =假设!$G$53 | D24: =假设!$G$54 | E24: =假设!$G$55 | F24: 基准算法不加减净现金（PE 已反映利息收支）
A25: 参考：若再计入净现金，所需 2030E 份额 | B25: 比例 | C25: =IF(C18*C17*C15=0,0,MAX(0,C10-C24)*(1+C12)^C13/C15/(C18*C17)) | D25: =IF(D18*D17*D15=0,0,MAX(0,D10-D24)*(1+D12)^D13/D15/(D18*D17)) | E25: =IF(E18*E17*E15=0,0,MAX(0,E10-E24)*(1+E12)^E13/E15/(E18*E17)) | F25: 净负债公司（安培龙）所需份额会更高
A27: 方法说明：
A28: ① 原有业务价值 = 2025A 扣非净利润 × PE。扣非利润已包含利息收支，所以基准算法不再单独加减净现金；第 25 行给出加回后的结果。
A29: ② 交易性金融资产、其他非流动金融资产、其他权益工具投资、长期股权投资按 2026-06-30 账面值加回，未做公允价值重估。
A30: ④ 2030E 利润按前瞻 PE 在 2029 年末定价，再按股权折现率折回报告日；折现率与年数为作者假设。
A31: 柯力、安培龙的市值还反映协作机器人力传感器、汽车 EMB 力传感器、并购等其他预期，不能全部归因于人形六维力。
A32: 本页只回答“当前价格隐含什么”，不构成投资建议。

Sheet 敏感性
A1: 敏感性分析（2030E，整机出货和费用率按情景开关取值）
A3: 表 1：2030E 中国人形六维力市场规模（亿元）
A4: 有效颗/台 ↓ ／ 单价（元/颗）→ | B4: 3600 | C4: 3900 | D4: 5000 | E4: 5800 | F4: 6300 | G4: 单价锚点：中金约 3,600、GGII 约 3,900、赛迪 5,000
A5: 0.7 | B5: =假设!$G$23*$A5*B$4/10000 | C5: =假设!$G$23*$A5*C$4/10000 | D5: =假设!$G$23*$A5*D$4/10000 | E5: =假设!$G$23*$A5*E$4/10000 | F5: =假设!$G$23*$A5*F$4/10000 | G5: 有效颗/台锚点：GGII ≈ 1.0、中金/本文基准 1.65、赛迪 ≈ 3.0
A6: 1 | B6: =假设!$G$23*$A6*B$4/10000 | C6: =假设!$G$23*$A6*C$4/10000 | D6: =假设!$G$23*$A6*D$4/10000 | E6: =假设!$G$23*$A6*E$4/10000 | F6: =假设!$G$23*$A6*F$4/10000
A7: 1.65 | B7: =假设!$G$23*$A7*B$4/10000 | C7: =假设!$G$23*$A7*C$4/10000 | D7: =假设!$G$23*$A7*D$4/10000 | E7: =假设!$G$23*$A7*E$4/10000 | F7: =假设!$G$23*$A7*F$4/10000
A8: 2.2 | B8: =假设!$G$23*$A8*B$4/10000 | C8: =假设!$G$23*$A8*C$4/10000 | D8: =假设!$G$23*$A8*D$4/10000 | E8: =假设!$G$23*$A8*E$4/10000 | F8: =假设!$G$23*$A8*F$4/10000
A9: 2.8 | B9: =假设!$G$23*$A9*B$4/10000 | C9: =假设!$G$23*$A9*C$4/10000 | D9: =假设!$G$23*$A9*D$4/10000 | E9: =假设!$G$23*$A9*E$4/10000 | F9: =假设!$G$23*$A9*F$4/10000
A12: 表 2：柯力传感 2030E 相关业务净利润（亿元）
A13: 份额 ↓ ／ 毛利率 → | B13: 0.3 | C13: 0.35 | D13: 0.4 | E13: 0.45 | F13: 0.5 | G13: ="对照：柯力 2025 扣非净利润 "&TEXT(假设!$G$43,"0.00")&" 亿元"
A14: 0.03 | B14: =需求情景!$H$11*$A14*(B$13-假设!$G$33)*(1-假设!$G$34) | C14: =需求情景!$H$11*$A14*(C$13-假设!$G$33)*(1-假设!$G$34) | D14: =需求情景!$H$11*$A14*(D$13-假设!$G$33)*(1-假设!$G$34) | E14: =需求情景!$H$11*$A14*(E$13-假设!$G$33)*(1-假设!$G$34) | F14: =需求情景!$H$11*$A14*(F$13-假设!$G$33)*(1-假设!$G$34)
A15: 0.05 | B15: =需求情景!$H$11*$A15*(B$13-假设!$G$33)*(1-假设!$G$34) | C15: =需求情景!$H$11*$A15*(C$13-假设!$G$33)*(1-假设!$G$34) | D15: =需求情景!$H$11*$A15*(D$13-假设!$G$33)*(1-假设!$G$34) | E15: =需求情景!$H$11*$A15*(E$13-假设!$G$33)*(1-假设!$G$34) | F15: =需求情景!$H$11*$A15*(F$13-假设!$G$33)*(1-假设!$G$34)
A16: 0.08 | B16: =需求情景!$H$11*$A16*(B$13-假设!$G$33)*(1-假设!$G$34) | C16: =需求情景!$H$11*$A16*(C$13-假设!$G$33)*(1-假设!$G$34) | D16: =需求情景!$H$11*$A16*(D$13-假设!$G$33)*(1-假设!$G$34) | E16: =需求情景!$H$11*$A16*(E$13-假设!$G$33)*(1-假设!$G$34) | F16: =需求情景!$H$11*$A16*(F$13-假设!$G$33)*(1-假设!$G$34)
A17: 0.12 | B17: =需求情景!$H$11*$A17*(B$13-假设!$G$33)*(1-假设!$G$34) | C17: =需求情景!$H$11*$A17*(C$13-假设!$G$33)*(1-假设!$G$34) | D17: =需求情景!$H$11*$A17*(D$13-假设!$G$33)*(1-假设!$G$34) | E17: =需求情景!$H$11*$A17*(E$13-假设!$G$33)*(1-假设!$G$34) | F17: =需求情景!$H$11*$A17*(F$13-假设!$G$33)*(1-假设!$G$34)
A18: 0.15 | B18: =需求情景!$H$11*$A18*(B$13-假设!$G$33)*(1-假设!$G$34) | C18: =需求情景!$H$11*$A18*(C$13-假设!$G$33)*(1-假设!$G$34) | D18: =需求情景!$H$11*$A18*(D$13-假设!$G$33)*(1-假设!$G$34) | E18: =需求情景!$H$11*$A18*(E$13-假设!$G$33)*(1-假设!$G$34) | F18: =需求情景!$H$11*$A18*(F$13-假设!$G$33)*(1-假设!$G$34)

Sheet 数据底稿
A1: ID | B1: 模块 | C1: 公司 | D1: 指标 | E1: 原文要点 | F1: 原始来源 | G1: 日期 | H1: 性质 | I1: 数值 | J1: 本文采用值 | K1: 局限 | L1: URL / 本地文件 + 页码 | M1: 可信度
A2: C-01 | B2: 公司 | C2: 柯力传感 | D2: 送样 / 样品验收 | E2: 样品客户已测试合格，订单已完成交付；能否获小批量订单尚不确定 | F2: 上证e互动回复（媒体转述） | G2: 2024-12-30 | H2: 实际 | I2: — | K2: 投资者问的是华为，公司未确认客户名 | L2: https://www.stcn.com/article/detail/1472756.html | M2: 中
A3: C-02 | B3: 公司 | C3: 柯力传感 | D3: 批量订单（协作机器人） | E3: 六维力传感器已取得部分协作机器人客户批量订单 | F3: 上证e互动 | G3: 2024-12-30 | H3: 实际 | I3: — | K3: 对 2024 年业绩影响较小 | L3: https://www.nbd.com.cn/articles/2024-12-30/3705529.html | M3: 高
A4: C-03 | B4: 公司 | C4: 柯力传感 | D4: 批量供货 | E4: 六维力已实现向部分客户批量供货，营收占比较小 | F4: 上证e互动 | G4: 2025-03-03 | H4: 实际 | I4: — | K4: 未给数量 | L4: https://finance.sina.com.cn/stock/relnews/cn/2025-03-03/doc-inenkmnh6637483.shtml | M4: 高
A5: C-04 | B5: 公司 | C5: 柯力传感 | D5: 批量出货（AI理疗） | E5: AI理疗机器人用六维力 25H1 已批量出货数百台 | F5: 上证e互动 | G5: 2025-07-07 | H5: 实际 | I5: 数百台 | K5: 非人形场景 | L5: https://finance.sina.com.cn/stock/relnews/dongmiqa/2025-07-07/doc-inferrrp6286638.shtml | M5: 高
A6: C-05 | B6: 公司 | C6: 柯力传感 | D6: 人形客户阶段 | E6: 已给国内多家人形客户送样，尚未进入量产采购阶段 | F6: 上证e互动 | G6: 2025-07-07 | H6: 实际 | I6: — | K6: 截至 2025-07 | L6: 同上 | M6: 高
A7: C-06 | B7: 公司 | C7: 柯力传感 | D7: 25H1 出货 / 送样 | E7: 送样 50 多家；六维力出货近千套；部分进入小批量 | F7: 2025 半年报（媒体转述） | G7: 2025-08-28 | H7: 实际 | I7: ≈1000 套；送样 50+ 家 | K7: 来自转述，未读原文 | L7: https://sensor.ofweek.com/2025-09/ART-81013-8120-30669803.html | M7: 中
A8: C-07 | B8: 公司 | C8: 柯力传感 | D8: 2025 全年出货 | E8: 2025 年机器人力学传感器销量超 1500 只，送样超 70 家 | F8: 2025 年度业绩说明会公告（编号 2026-016，PDF 原文） | G8: 2026-05-29 会 / 05-30 公告 | H8: 实际 | I8: >1500 只；>70 家 | K8: "力学传感器"含关节力矩，未拆分六维力 | L8: http://file.finance.sina.com.cn/211.154.219.97:9494/MRGG/CNSESH_STOCK/2026/2026-5/2026-05-30/12362018.PDF | M8: 高
A9: C-08 | B9: 公司 | C9: 柯力传感 | D9: 人形批量出货 | E9: AI理疗及开普勒人形机器人产品均实现数百台批量出货 | F9: 同上（问题 2） | G9: 2026-05-29 | H9: 实际 | I9: 数百台 | J9: 假设：柯力传感 2030E 份额 | K9: 开普勒是柯力参股公司，属关联方，不是独立第三方客户 | L9: 同上 | M9: 高
A10: C-09 | B10: 公司 | C10: 柯力传感 | D10: 间接进入车企链 | E10: 部分传感器产品经下游客户间接进入小鹏供应链 | F10: 同上（问题 6） | G10: 2026-05-29 | H10: 实际 | I10: — | K10: 间接供货；未说明是否为六维力 | L10: 同上 | M10: 高
A11: C-10 | B11: 公司 | C11: 柯力传感 | D11: 产能 | E11: 产能方面不断提高（未给具体数字） | F11: 同上（问题 5） | G11: 2026-05-29 | H11: 实际（定性） | I11: 未披露 | K11: 投资者直接问产能，公司回避 | L11: 同上 | M11: 高
A12: C-11 | B12: 公司 | C12: 柯力传感 | D12: 批量订单 / 头部验证 | E12: 六维力部分客户已取得批量订单，多家头部客户处于验证阶段 | F12: 上证e互动 | G12: 2026-06-01 | H12: 实际 | I12: — | K12: 收入占比仍较小 | L12: https://finance.sina.com.cn/stock/relnews/cn/2026-06-01/doc-inhzxmem2262203.shtml | M12: 高
A13: C-12 | B13: 公司 | C13: 柯力传感 | D13: 26H1 出货 | E13: 1-6 月机器人力学传感器销售超 2000 只，超 25 年全年 | F13: 2026 半年报 p9（本地 PDF） | G13: 2026-08-28 | H13: 实际 | I13: >2000 只 | J13: 假设：柯力传感 2026E 份额 | K13: 含关节力矩；未拆分六维力 | L13: 本地 PDF；https://stockmc.xueqiu.com/202608/603662_20260828_010I.pdf | M13: 高
A14: C-13 | B14: 公司 | C14: 柯力传感 | D14: 月订单 | E14: 自 4 月份以来，月订单量持续突破千只 | F14: 2026 半年报 p9 | G14: 2026-08-28 | H14: 实际 | I14: >1000 只/月 | K14: 是订单量，不等于交付量 | L14: 同上 | M14: 高
A15: C-14 | B15: 公司 | C15: 柯力传感 | D15: 送样客户 | E15: 累计向超 90 家人形、协作、工业机器人企业送样 | F15: 2026 半年报 p9 | G15: 2026-08-28 | H15: 实际 | I15: >90 家 | J15: 假设：柯力传感 2030E 份额 | K15: 送样客户数从 50+（25H1）、70+（25 年）增至 90+ | L15: 同上 | M15: 高
A16: C-15 | B16: 公司 | C16: 柯力传感 | D16: 阶段定性 | E16: 由小批量生产加快向批量化供应过渡 | F16: 2026 半年报 p9 | G16: 2026-08-28 | H16: 实际 | I16: — | J16: 假设：柯力传感 2030E 份额 | K16: 尚未达到"大批量 / 定点" | L16: 同上 | M16: 高
A17: C-16 | B17: 公司 | C17: 柯力传感 | D17: 头部客户 | E17: 部分客户已取得批量订单，多家头部客户处于验证阶段 | F17: 2026 半年报 p9 / p11 | G17: 2026-08-28 | H17: 实际 | I17: — | J17: 假设：柯力传感 2030E 份额 | K17: 未披露客户名、定点或长期协议 | L17: 同上 | M17: 高
A18: C-17 | B18: 公司 | C18: 柯力传感 | D18: 整车链 | E18: 部分传感器已通过下游客户间接进入整车企业供应链 | F18: 2026 半年报 p9 | G18: 2026-08-28 | H18: 实际 | I18: — | K18: 与 C-09 小鹏对应 | L18: 同上 | M18: 高
A19: C-18 | B19: 公司 | C19: 柯力传感 | D19: 产线 | E19: 自动化标定与检测产线运行稳定，产能持续提升 | F19: 2026 半年报 p9 / p11 | G19: 2026-08-28 | H19: 实际（定性） | I19: 未披露 | K19: 机器人传感器产能无数字；"年产传感器 300 万台"是全公司口径 | L19: 同上 | M19: 高
A20: C-19 | B20: 公司 | C20: 柯力传感 | D20: 技术 | E20: 掌握六维力结构解耦、算法解耦、高速采样等技术 | F20: 2026 半年报 p11 | G20: 2026-08-28 | H20: 实际（自述） | I20: — | K20: 自述 | L20: 同上 | M20: 高
A21: C-20 | B21: 公司 | C21: 柯力传感 | D21: 下半年计划 | E21: 聚焦机器人传感器，推进重点客户突破、产能提升 | F21: 2026 半年报 p10 | G21: 2026-08-28 | H21: 计划 | I21: — | K21: 无量化目标 | L21: 同上 | M21: 高
A22: C-21 | B22: 公司 | C22: 柯力传感 | D22: 2026 全年出货预期 | E22: 力传感月出货上千台，全年有望达 1.2 万只 | F22: 国金证券研报摘要 | G22: 2026-04-29 | H22: 测算（券商） | I22: 1.2 万只 | J22: 假设：柯力传感 2026E 份额 | K22: 是券商预期，不是公司指引 | L22: https://www.ai-gupiao.com/research/summary/32112 | M22: 中
A23: C-22 | B23: 公司 | C23: 柯力传感 | D23: 单价 / 产能（传闻） | E23: 宁波六维力年产能 10 万套；单价 8000-12000 元；特斯拉目标价 1800 美元 | F23: 雪球、股吧 | G23: 2025-2026 | H23: 传闻 | I23: — | K23: 无官方出处，仅作线索 | L23: https://xueqiu.com/9812945708/351864145 | M23: 低
A24: C-23 | B24: 公司 | C24: 柯力传感 | D24: 客户（传闻） | E24: 向特斯拉送样六维力 | F24: 雪球 | G24: 2025 | H24: 传闻 | I24: — | K24: 公司在业绩会上对宇树、华为、特斯拉提问不置可否 | L24: 同上 | M24: 低
A25: C-24 | B25: 公司 | C25: 柯力传感 | D25: 2025 营收 / 利润 | E25: 营收 15.58 亿 +20.33%；归母 3.41 亿 +30.73%；扣非 2.14 亿 +11.06% | F25: 2025 年报（媒体转述） | G25: 2026-04-27 | H25: 实际 | I25: 见左 | J25: 假设：柯力传感 原有业务净利润（2025 扣非） | K25: 归母含大额公允价值收益 | L25: https://m.jiemian.com/article/14335991.html | M25: 中
A26: C-25 | B26: 公司 | C26: 柯力传感 | D26: 2025 毛利率 | E26: 毛利率 44.83%，同比 +1.71pct | F26: 年报（媒体转述） | G26: 2026-04 | H26: 实际 | I26: 44.83% | J26: 假设：相关业务毛利率 | K26: 未读年报原文 | L26: 同上 | M26: 中
A27: C-26 | B27: 公司 | C27: 柯力传感 | D27: 2025 分业务 | E27: 传统力学传感器及仪表 6.20 亿（-1.73%）；其他物理量传感器 2.52 亿；工业物联网及系统集成 5.89 亿，毛利率 47.93% | F27: 华创证券研报摘要 | G27: 2026-04-30 | H27: 实际（转述） | I27: 见左 | K27: 机器人传感器未单列 | L27: https://m.hibor.com.cn/wap_detail.aspx?id=ef8780a0618131fed1cbc6d8f62d007a | M27: 中
A28: C-27 | B28: 公司 | C28: 柯力传感 | D28: 26H1 营收 / 利润 | E28: 营收 8.38 亿 +22.27%；归母 1.31 亿 -24.38%；扣非 1.36 亿 +24.89% | F28: 2026 半年报 p5（本地 PDF） | G28: 2026-08-28 | H28: 实际 | I28: 837,754,477.62 元 / 130,688,021.76 元 / 135,595,893.56 元 | K28: 归母下降主要因驰诚股份公允价值下跌；营收增长主要因并购子公司并表 | L28: 本地 PDF | M28: 高
A29: C-28 | B29: 公司 | C29: 柯力传感 | D29: 26H1 毛利率 | E29: 营业收入 8.378 亿，营业成本 4.547 亿 | F29: 2026 半年报 p12 | G29: 2026-08-28 | H29: 测算 | I29: 45.72% | K29: 无传感器或机器人分部毛利率 | L29: 本地 PDF | M29: 高
A30: C-29 | B30: 公司 | C30: 柯力传感 | D30: 26H1 研发 | E30: 研发费用 7,343 万，+14.32% | F30: 2026 半年报 p12 | G30: 2026-08-28 | H30: 实际 | I30: 0.73 亿 | K30: — | L30: 本地 PDF | M30: 高
A31: C-30 | B31: 公司 | C31: 柯力传感 | D31: 市值 / PE | E31: 总市值约 122 亿元；PE（动态）46.77，PE（静态）35.90 | F31: 同花顺 F10 | G31: 2026-10-20 查询（页面未标行情日期，融资融券数据截至 10-19） | H31: 实际 | I31: 122 亿 / 46.8x | J31: （已由 F 系列 2026-10-19 统一口径复核取代） | K31: 页面编码异常，取值以行情软件为准 | L31: https://basic.10jqka.com.cn/603662/ | M31: 中
A32: C-31 | B32: 公司 | C32: 安培龙 | D32: 力矩传感器小批量 | E32: 机器人用力矩传感器已接小批量订单，交付验证中 | F32: 互动易（媒体转述） | G32: 2024-12-04 | H32: 实际 | I32: — | K32: 是力矩传感器，不是六维力 | L32: https://news.qq.com/rain/a/20241204A05O7S00 | M32: 中
A33: C-32 | B33: 公司 | C33: 安培龙 | D33: 六维力研发 | E33: 六维力传感器处于样品研发阶段，尚未实现交样 | F33: 互动易 | G33: 2025-03-04 | H33: 实际 | I33: — | K33: — | L33: https://www.nbd.com.cn/articles/2025-03-04/3775443.html | M33: 高
A34: C-33 | B34: 公司 | C34: 安培龙 | D34: 六维力送样 | E34: 金属应变式六维力已完成开发，在部分人形及按摩机器人厂商送样 | F34: 互动易 | G34: 2025-08-21 | H34: 实际 | I34: — | K34: MEMS 路线当时仍在研发 | L34: https://m.nbd.com.cn/articles/2025-08-21/4021837.html | M34: 高
A35: C-34 | B35: 公司 | C35: 安培龙 | D35: 特斯拉 | E35: 暂未给您所提及的公司送样六维力传感器 | F35: 互动易（媒体转述） | G35: 2025-10-27 | H35: 实际 | I35: — | K35: 否认了特斯拉送样 | L35: 转述，见搜索结果 | M35: 中
A36: C-35 | B36: 公司 | C36: 安培龙 | D36: 募投产能 | E36: 定增力传感器产线项目新增年产约 50 万只，含六维力 | F36: 定增预案 | G36: 2026-01-07 | H36: 计划 | I36: 50 万只/年；达产毛利率 37.77% | J36: 假设：相关业务毛利率；假设：安培龙 2030E 份额 | K36: 50 万只含拉压力和力矩传感器，未拆分六维力 | L36: https://finance.sina.com.cn/stock/s/2026-01-08/doc-inhfpfxi7234461.shtml | M36: 高
A37: C-36 | B37: 公司 | C37: 安培龙 | D37: 定增进度 | E37: 深交所 5-28 审核通过；证监会 6-26 同意注册（证监许可〔2026〕1513 号） | F37: 公司公告（媒体转述） | G37: 2026-06-26 | H37: 实际 | I37: 募资 ≤5.44 亿 | K37: 未查到发行完成信息 | L37: https://app.myzaker.com/article/6a4637898e9f093a2657a73b | M37: 中
A38: C-37 | B38: 公司 | C38: 安培龙 | D38: 机器人力传感器批量 | E38: 公司用于机器人的力传感器产品已实现批量交付 | F38: 2026 半年报（PDF 原文） | G38: 2026-08-28 | H38: 实际 | I38: — | K38: "力传感器"未限定为六维力 | L38: http://file.finance.sina.com.cn/211.154.219.97:9494/MRGG/CNSESZ_STOCK/2026/2026-8/2026-08-28/12555790.PDF | M38: 高
A39: C-38 | B39: 公司 | C39: 安培龙 | D39: 六维力小批量 | E39: 六维力已完成开发……部分客户已处于小批量交付阶段 | F39: 投资者关系活动记录表 20260907（PDF） | G39: 2026-09-07 | H39: 实际 | I39: — | J39: 假设：安培龙 2026E 份额 | K39: 不披露客户 | L39: http://file.finance.sina.com.cn/211.154.219.97:9494/MRGG/CNSESZ_STOCK/2026/2026-9/2026-09-07/12587659.PDF | M39: 高
A40: C-39 | B40: 公司 | C40: 安培龙 | D40: 批量订单 | E40: 含两种路线六维力等；部分客户已取得批量订单并实现批量生产交付 | F40: 投资者关系活动记录表 20260930（编号 2026-010） | G40: 2026-09-30 | H40: 实际 | I40: — | J40: 假设：安培龙 2026E 份额；假设：安培龙 2030E 份额 | K40: 同时声明收入占比低，不构成重大影响；未拆分哪类产品获批量 | L40: http://file.finance.sina.com.cn/211.154.219.97:9494/MRGG/CNSESZ_STOCK/2026/2026-9/2026-09-30/12629237.PDF | M40: 高
...
